Workbook

Sheet Planilha1
A1: Código IBGE | B1: MUNICÍPIO | C1: ANO | D1: Orçamento | E1: Despesa Educação | F1: Receita Cota-parte ICMS Estimada | G1: Receita Fundeb Estimada | H1: Cota-parte ICMS Realizada | I1: ICMS Educacional | J1: Representatividade do ICMS Educacional | K1: Receita da contribuição de estados e municípios ao Fundeb | L1: Complementação VAAF | M1: Complementação VAAT | N1: Complementação VAAR | O1: VAAT anterior à Complementação-VAAT (art. 16, IV) (R$) | P1: VAAT com a Complementação da União-VAAT (art. 16, V) (R$) | Q1: Coeficientes de distribuição da complementação da União-VAAR | R1: Habilitado ao VAAT? | S1: VAAT Mínimo Brasil
A2: 3200102 | B2: AFONSO CLAUDIO | C2: 2020 | D2: 84714408 | E2: 28764008 | F2: 22750000 | G2: 15300000 | I2: 0 | O2: - | P2: - | Q2: -
A3: 3200102 | B3: AFONSO CLAUDIO | C3: 2021 | D3: 89877500 | E3: 28950950 | F3: 23950000 | G3: 16475450 | H3: 24457174 | I3: 0 | K3: =VLOOKUP($A3,Fundeb2021!$C:$H,3,0) -> 20242709 | L3: =VLOOKUP($A3,Fundeb2021!$C:$H,4,0) -> - | M3: =VLOOKUP($A3,Fundeb2021!$C:$H,5,0) -> - | N3: =VLOOKUP($A3,Fundeb2021!$C:$H,6,0) -> - | O3: 4918.46 | P3: 4918.46 | Q3: - | R3: Habilitado para o cálculo do VAAT. | S3: R$ 4.846,26
A4: 3200102 | B4: AFONSO CLAUDIO | C4: 2022 | D4: 97306801 | E4: 29224226 | F4: 25622500 | G4: 17299222 | H4: 26550722 | I4: 0 | K4: =VLOOKUP($A4,Fundeb2022!$C:$H,3,0) -> 22384988 | L4: =VLOOKUP($A4,Fundeb2022!$C:$H,4,0) -> - | M4: =VLOOKUP($A4,Fundeb2022!$C:$H,5,0) -> 1568591.3 | N4: =VLOOKUP($A4,Fundeb2022!$C:$H,6,0) -> - | O4: 5339.73 | P4: 5664.21 | Q4: - | R4: Habilitado para o cálculo do VAAT. | S4: R$ 5.664,21
A5: 3200102 | B5: AFONSO CLAUDIO | C5: 2023 | D5: 126680000 | E5: 41202499 | F5: 31600000 | G5: 23500000 | H5: 26859314 | I5: 0 | K5: =VLOOKUP($A5,Fundeb2023!$C:$H,3,0) -> 24293438 | L5: =VLOOKUP($A5,Fundeb2023!$C:$H,4,0) -> - | M5: =VLOOKUP($A5,Fundeb2023!$C:$H,5,0) -> 1630680.6 | N5: =VLOOKUP($A5,Fundeb2023!$C:$H,6,0) -> 250051.14 | O5: 7883.14 | P5: 8196.52 | Q5: 0.00014342158 | R5: Habilitado para o cálculo do VAAT. | S5: R$ 8.196,52
A6: 3200102 | B6: AFONSO CLAUDIO | C6: 2024 | D6: 131900000 | E6: 42334958 | F6: 31801000 | G6: 25306000 | H6: 30373719 | I6: 0 | K6: =VLOOKUP($A6,Fundeb2024!$C:$H,3,0) -> 28088702 | L6: =VLOOKUP($A6,Fundeb2024!$C:$H,4,0) -> - | M6: =VLOOKUP($A6,Fundeb2024!$C:$H,5,0) -> 3799211.9 | N6: =VLOOKUP($A6,Fundeb2024!$C:$H,6,0) -> 355742.77 | O6: 7762.91 | P6: 8510.81 | Q6: 9.058e-05 | R6: Habilitado para o cálculo do VAAT. | S6: R$ 8.481,21
A7: 3200102 | B7: AFONSO CLAUDIO | C7: 2025 | D7: 181795000 | E7: 58887906 | F7: 37800000 | G7: 29580650 | H7: 36854003 | I7: =VLOOKUP(A7,'Página1'!A:E,5,0) -> 7049378 | J7: =I7/H7 -> 0.19127849 | K7: =VLOOKUP($A7,Fundeb2025!$C:$H,3,0) -> 31002477 | L7: =VLOOKUP($A7,Fundeb2025!$C:$H,4,0) -> - | M7: =VLOOKUP($A7,Fundeb2025!$C:$H,5,0) -> 4067327.4 | N7: =VLOOKUP($A7,Fundeb2025!$C:$H,6,0) -> 2122479.2 | O7: 7252.8 | P7: 8031.01 | Q7: 0.00041581834 | R7: Habilitado para o cálculo do VAAT. | S7: R$ 8.031,01
A8: 3200169 | B8: AGUA DOCE DO NORTE | C8: 2020 | D8: 39700000 | I8: 0 | Q8: -
A9: 3200169 | B9: AGUA DOCE DO NORTE | C9: 2021 | D9: 40900000 | H9: 9137446.3 | I9: 0 | K9: =VLOOKUP($A9,Fundeb2021!$C:$H,3,0) -> 8099381.8 | L9: =VLOOKUP($A9,Fundeb2021!$C:$H,4,0) -> - | M9: =VLOOKUP($A9,Fundeb2021!$C:$H,5,0) -> - | N9: =VLOOKUP($A9,Fundeb2021!$C:$H,6,0) -> - | O9: 5459.52 | P9: 5459.52 | Q9: - | R9: Habilitado para o cálculo do VAAT. | S9: R$ 4.846,26
A10: 3200169 | B10: AGUA DOCE DO NORTE | C10: 2022 | D10: 41200000 | E10: 5438568 | F10: 8471852 | G10: 7136895.1 | H10: 10050616 | I10: 0 | K10: =VLOOKUP($A10,Fundeb2022!$C:$H,3,0) -> 8853120 | L10: =VLOOKUP($A10,Fundeb2022!$C:$H,4,0) -> - | M10: =VLOOKUP($A10,Fundeb2022!$C:$H,5,0) -> - | N10: =VLOOKUP($A10,Fundeb2022!$C:$H,6,0) -> - | O10: - | P10: - | Q10: - | R10: Inabilitado. Inobservância do art. 38 da Lei nº 14.113/20. | S10: R$ 5.664,21
A11: 3200169 | B11: AGUA DOCE DO NORTE | C11: 2023 | D11: 57600000 | E11: 16312242 | H11: 10203470 | I11: 0 | K11: =VLOOKUP($A11,Fundeb2023!$C:$H,3,0) -> 9952336 | L11: =VLOOKUP($A11,Fundeb2023!$C:$H,4,0) -> - | M11: =VLOOKUP($A11,Fundeb2023!$C:$H,5,0) -> - | N11: =VLOOKUP($A11,Fundeb2023!$C:$H,6,0) -> - | O11: - | P11: - | Q11: - | R11: Inobservância do art. 38 da Lei nº 14.113/20. | S11: R$ 8.196,52
A12: 3200169 | B12: AGUA DOCE DO NORTE | C12: 2024 | D12: 62400000 | E12: 17067210 | H12: 11708539 | I12: 0 | K12: =VLOOKUP($A12,Fundeb2024!$C:$H,3,0) -> 11634139 | L12: =VLOOKUP($A12,Fundeb2024!$C:$H,4,0) -> - | M12: =VLOOKUP($A12,Fundeb2024!$C:$H,5,0) -> 1193886.9 | N12: =VLOOKUP($A12,Fundeb2024!$C:$H,6,0) -> 199550.57 | O12: 7931.94 | P12: 8510.81 | Q12: 5.108e-05 | R12: Habilitado para o cálculo do VAAT. | S12: R$ 8.481,21
A13: 3200169 | B13: AGUA DOCE DO NORTE | C13: 2025 | D13: 69800000 | E13: 20250642 | H13: 16959475 | I13: =VLOOKUP(A13,'Página1'!A:E,5,0) -> 7561585.1 | J13: =I13/H13 -> 0.44586197 | K13: =VLOOKUP($A13,Fundeb2025!$C:$H,3,0) -> 12167424 | L13: =VLOOKUP($A13,Fundeb2025!$C:$H,4,0) -> - | M13: =VLOOKUP($A13,Fundeb2025!$C:$H,5,0) -> 368893.21 | N13: =VLOOKUP($A13,Fundeb2025!$C:$H,6,0) -> 832701.63 | O13: 7846.18 | P13: 8031.01 | Q13: 0.00016313592 | R13: Habilitado para o cálculo do VAAT. | S13: R$ 8.031,01
A14: 3200136 | B14: AGUIA BRANCA | C14: 2020 | D14: 45385592 | E14: 13459645 | I14: 0 | Q14: -
A15: 3200136 | B15: AGUIA BRANCA | C15: 2021 | D15: 47083014 | E15: 14138856 | H15: 13003588 | I15: 0 | K15: =VLOOKUP($A15,Fundeb2021!$C:$H,3,0) -> 7877882.8 | L15: =VLOOKUP($A15,Fundeb2021!$C:$H,4,0) -> - | M15: =VLOOKUP($A15,Fundeb2021!$C:$H,5,0) -> - | N15: =VLOOKUP($A15,Fundeb2021!$C:$H,6,0) -> - | O15: 5174.8 | P15: 5174.8 | Q15: - | R15: Habilitado para o cálculo do VAAT. | S15: R$ 4.846,26
A16: 3200136 | B16: AGUIA BRANCA | C16: 2022 | D16: 49386934 | E16: 14487366 | H16: 13837510 | I16: 0 | K16: =VLOOKUP($A16,Fundeb2022!$C:$H,3,0) -> 8522131.7 | L16: =VLOOKUP($A16,Fundeb2022!$C:$H,4,0) -> - | M16: =VLOOKUP($A16,Fundeb2022!$C:$H,5,0) -> - | N16: =VLOOKUP($A16,Fundeb2022!$C:$H,6,0) -> - | O16: 5906.16 | P16: 5906.16 | Q16: - | R16: Habilitado para o cálculo do VAAT. | S16: R$ 5.664,21
A17: 3200136 | B17: AGUIA BRANCA | C17: 2023 | D17: 57782713 | E17: 16491871 | H17: 14349253 | I17: 0 | K17: =VLOOKUP($A17,Fundeb2023!$C:$H,3,0) -> 9570195.3 | L17: =VLOOKUP($A17,Fundeb2023!$C:$H,4,0) -> - | M17: =VLOOKUP($A17,Fundeb2023!$C:$H,5,0) -> - | N17: =VLOOKUP($A17,Fundeb2023!$C:$H,6,0) -> 194236.85 | O17: 8269.03 | P17: 8269.03 | Q17: 0.00011140823 | R17: Habilitado para o cálculo do VAAT. | S17: R$ 8.196,52
A18: 3200136 | B18: AGUIA BRANCA | C18: 2024 | D18: 74500000 | E18: 21765000 | H18: 19092691 | I18: 0 | K18: =VLOOKUP($A18,Fundeb2024!$C:$H,3,0) -> 11467093 | L18: =VLOOKUP($A18,Fundeb2024!$C:$H,4,0) -> - | M18: =VLOOKUP($A18,Fundeb2024!$C:$H,5,0) -> 1303922.7 | N18: =VLOOKUP($A18,Fundeb2024!$C:$H,6,0) -> 328054.69 | O18: 7868.95 | P18: 8510.81 | Q18: 8.379e-05 | R18: Habilitado para o cálculo do VAAT. | S18: R$ 8.481,21
A19: 3200136 | B19: AGUIA BRANCA | C19: 2025 | D19: 87000000 | E19: 24833040 | H19: 28482349 | I19: =VLOOKUP(A19,'Página1'!A:E,5,0) -> 8293670 | J19: =I19/H19 -> 0.29118631 | K19: =VLOOKUP($A19,Fundeb2025!$C:$H,3,0) -> 12501564 | L19: =VLOOKUP($A19,Fundeb2025!$C:$H,4,0) -> - | M19: =VLOOKUP($A19,Fundeb2025!$C:$H,5,0) -> 1230681 | N19: =VLOOKUP($A19,Fundeb2025!$C:$H,6,0) -> 839799.25 | O19: 7436.15 | P19: 8031.01 | Q19: 0.00016452643 | R19: Habilitado para o cálculo do VAAT. | S19: R$ 8.031,01
A20: 3200201 | B20: ALEGRE | C20: 2020 | D20: 92300000 | E20: 22766000 | I20: 0 | Q20: -
A21: 3200201 | B21: ALEGRE | C21: 2021 | D21: 93500000 | E21: 22553500 | H21: 14834279 | I21: 0 | K21: =VLOOKUP($A21,Fundeb2021!$C:$H,3,0) -> 13902117 | L21: =VLOOKUP($A21,Fundeb2021!$C:$H,4,0) -> - | M21: =VLOOKUP($A21,Fundeb2021!$C:$H,5,0) -> - | N21: =VLOOKUP($A21,Fundeb2021!$C:$H,6,0) -> - | O21: 4947.26 | P21: 4947.26 | Q21: - | R21: Habilitado para o cálculo do VAAT. | S21: R$ 4.846,26
A22: 3200201 | B22: ALEGRE | C22: 2022 | D22: 98000000 | E22: 22890000 | F22: 16000000 | G22: 11500000 | H22: 17745243 | I22: 0 | K22: =VLOOKUP($A22,Fundeb2022!$C:$H,3,0) -> 15360469 | L22: =VLOOKUP($A22,Fundeb2022!$C:$H,4,0) -> - | M22: =VLOOKUP($A22,Fundeb2022!$C:$H,5,0) -> 778556.81 | N22: =VLOOKUP($A22,Fundeb2022!$C:$H,6,0) -> - | O22: 5441.62 | P22: 5664.21 | Q22: - | R22: Habilitado para o cálculo do VAAT. | S22: R$ 5.664,21
A23: 3200201 | B23: ALEGRE | C23: 2023 | D23: 112500000 | E23: 28949000 | H23: 17590421 | I23: 0 | K23: =VLOOKUP($A23,Fundeb2023!$C:$H,3,0) -> 16685737 | L23: =VLOOKUP($A23,Fundeb2023!$C:$H,4,0) -> - | M23: =VLOOKUP($A23,Fundeb2023!$C:$H,5,0) -> 499888.27 | N23: =VLOOKUP($A23,Fundeb2023!$C:$H,6,0) -> - | O23: 8073.8 | P23: 8196.52 | Q23: - | R23: Habilitado para o cálculo do VAAT. | S23: R$ 8.196,52
A24: 3200201 | B24: ALEGRE | C24: 2024 | D24: 125000000 | E24: 33511700 | F24: 16000000 | G24: 14720000 | H24: 19416540 | I24: 0 | K24: =VLOOKUP($A24,Fundeb2024!$C:$H,3,0) -> 18874220 | L24: =VLOOKUP($A24,Fundeb2024!$C:$H,4,0) -> - | M24: =VLOOKUP($A24,Fundeb2024!$C:$H,5,0) -> - | N24: =VLOOKUP($A24,Fundeb2024!$C:$H,6,0) -> - | O24: 8625.34 | P24: 8625.34 | Q24: - | R24: Habilitado para o cálculo do VAAT. | S24: R$ 8.481,21
A25: 3200201 | B25: ALEGRE | C25: 2025 | D25: 138000000 | E25: 37567734 | F25: 19500000 | G25: 16850000 | H25: 22960854 | I25: =VLOOKUP(A25,'Página1'!A:E,5,0) -> 5703639.5 | J25: =I25/H25 -> 0.24840711 | K25: =VLOOKUP($A25,Fundeb2025!$C:$H,3,0) -> 20597543 | L25: =VLOOKUP($A25,Fundeb2025!$C:$H,4,0) -> - | M25: =VLOOKUP($A25,Fundeb2025!$C:$H,5,0) -> - | N25: =VLOOKUP($A25,Fundeb2025!$C:$H,6,0) -> 681629.81 | O25: 8064.11 | P25: - | Q25: 0.0001335392 | R25: Habilitado para o cálculo do VAAT. | S25: R$ 8.031,01
A26: 3200300 | B26: ALFREDO CHAVES | C26: 2020 | D26: 55900000 | E26: 13638507 | F26: 16000000 | G26: 9000000 | I26: 0 | Q26: -
A27: 3200300 | B27: ALFREDO CHAVES | C27: 2021 | D27: 58700000 | E27: 14545800 | H27: 14736930 | I27: 0 | K27: =VLOOKUP($A27,Fundeb2021!$C:$H,3,0) -> 10353244 | L27: =VLOOKUP($A27,Fundeb2021!$C:$H,4,0) -> - | M27: =VLOOKUP($A27,Fundeb2021!$C:$H,5,0) -> - | N27: =VLOOKUP($A27,Fundeb2021!$C:$H,6,0) -> - | O27: 6017.13 | P27: 6017.13 | Q27: - | R27: Habilitado para o cálculo do VAAT. | S27: R$ 4.846,26
A28: 3200300 | B28: ALFREDO CHAVES | C28: 2022 | D28: 74000000 | E28: 22616700 | H28: 16264061 | I28: 0 | K28: =VLOOKUP($A28,Fundeb2022!$C:$H,3,0) -> 11154523 | L28: =VLOOKUP($A28,Fundeb2022!$C:$H,4,0) -> - | M28: =VLOOKUP($A28,Fundeb2022!$C:$H,5,0) -> - | N28: =VLOOKUP($A28,Fundeb2022!$C:$H,6,0) -> - | O28: 6795.57 | P28: 6795.57 | Q28: - | R28: Habilitado para o cálculo do VAAT. | S28: R$ 5.664,21
A29: 3200300 | B29: ALFREDO CHAVES | C29: 2023 | D29: 79000000 | E29: 20951900 | H29: 16490171 | I29: 0 | K29: =VLOOKUP($A29,Fundeb2023!$C:$H,3,0) -> 12523154 | L29: =VLOOKUP($A29,Fundeb2023!$C:$H,4,0) -> - | M29: =VLOOKUP($A29,Fundeb2023!$C:$H,5,0) -> - | N29: =VLOOKUP($A29,Fundeb2023!$C:$H,6,0) -> 126120.11 | O29: 9616.71 | P29: 9616.71 | Q29: 7.2338584e-05 | R29: Habilitado para o cálculo do VAAT. | S29: R$ 8.196,52
A30: 3200300 | B30: ALFREDO CHAVES | C30: 2024 | D30: 87000000 | E30: 25701400 | F30: 22500000 | G30: 12800000 | H30: 19003916 | I30: 0 | K30: =VLOOKUP($A30,Fundeb2024!$C:$H,3,0) -> 15134500 | L30: =VLOOKUP($A30,Fundeb2024!$C:$H,4,0) -> - | M30: =VLOOKUP($A30,Fundeb2024!$C:$H,5,0) -> - | N30: =VLOOKUP($A30,Fundeb2024!$C:$H,6,0) -> 192795.46 | O30: 8839.55 | P30: 8839.55 | Q30: 4.909e-05 | R30: Habilitado para o cálculo do VAAT. | S30: R$ 8.481,21
A31: 3200300 | B31: ALFREDO CHAVES | C31: 2025 | D31: 100000000 | E31: 28305360 | F31: 24900000 | G31: 16000000 | H31: 24271123 | I31: =VLOOKUP(A31,'Página1'!A:E,5,0) -> 7221047.1 | J31: =I31/H31 -> 0.29751599 | K31: =VLOOKUP($A31,Fundeb2025!$C:$H,3,0) -> 16920124 | L31: =VLOOKUP($A31,Fundeb2025!$C:$H,4,0) -> - | M31: =VLOOKUP($A31,Fundeb2025!$C:$H,5,0) -> - | N31: =VLOOKUP($A31,Fundeb2025!$C:$H,6,0) -> - | O31: 8148.31 | P31: - | Q31: - | R31: Habilitado para o cálculo do VAAT. | S31: R$ 8.031,01
A32: 3200359 | B32: ALTO RIO NOVO | C32: 2020 | D32: 29198000 | E32: 9141980 | I32: 0 | Q32: -
A33: 3200359 | B33: ALTO RIO NOVO | C33: 2021 | D33: 31242000 | E33: 8395000 | H33: 7017729.1 | I33: 0 | K33: =VLOOKUP($A33,Fundeb2021!$C:$H,3,0) -> 5462663.7 | L33: =VLOOKUP($A33,Fundeb2021!$C:$H,4,0) -> - | M33: =VLOOKUP($A33,Fundeb2021!$C:$H,5,0) -> - | N33: =VLOOKUP($A33,Fundeb2021!$C:$H,6,0) -> - | O33: 5023.91 | P33: 5023.91 | Q33: - | R33: Habilitado para o cálculo do VAAT. | S33: R$ 4.846,26
A34: 3200359 | B34: ALTO RIO NOVO | C34: 2022 | D34: 35160000 | E34: 10986130 | H34: 7670167.8 | I34: 0 | K34: =VLOOKUP($A34,Fundeb2022!$C:$H,3,0) -> 5499686.1 | L34: =VLOOKUP($A34,Fundeb2022!$C:$H,4,0) -> - | M34: =VLOOKUP($A34,Fundeb2022!$C:$H,5,0) -> - | N34: =VLOOKUP($A34,Fundeb2022!$C:$H,6,0) -> - | O34: 6069.05 | P34: 6069.05 | Q34: - | R34: Habilitado para o cálculo do VAAT. | S34: R$ 5.664,21
A35: 3200359 | B35: ALTO RIO NOVO | C35: 2023 | D35: 42700000 | E35: 13653550 | H35: 7974042.5 | I35: 0 | K35: =VLOOKUP($A35,Fundeb2023!$C:$H,3,0) -> 5888653.2 | L35: =VLOOKUP($A35,Fundeb2023!$C:$H,4,0) -> - | M35: =VLOOKUP($A35,Fundeb2023!$C:$H,5,0) -> - | N35: =VLOOKUP($A35,Fundeb2023!$C:$H,6,0) -> - | O35: 8989.62 | P35: 8989.62 | Q35: - | R35: Habilitado para o cálculo do VAAT. | S35: R$ 8.196,52
A36: 3200359 | B36: ALTO RIO NOVO | C36: 2024 | D36: 50400000 | E36: 18764250 | F36: 500000 | G36: 6000000 | H36: 9754608.9 | I36: 0 | K36: =VLOOKUP($A36,Fundeb2024!$C:$H,3,0) -> 7394837.1 | L36: =VLOOKUP($A36,Fundeb2024!$C:$H,4,0) -> - | M36: =VLOOKUP($A36,Fundeb2024!$C:$H,5,0) -> 1119011 | N36: =VLOOKUP($A36,Fundeb2024!$C:$H,6,0) -> - | O36: 7676.28 | P36: 8510.81 | Q36: - | R36: Habilitado para o cálculo do VAAT. | S36: R$ 8.481,21
A37: 3200359 | B37: ALTO RIO NOVO | C37: 2025 | D37: 61500000 | E37: 19769100 | H37: 14159146 | I37: =VLOOKUP(A37,'Página1'!A:E,5,0) -> 6733282.2 | J37: =I37/H37 -> 0.47554296 | K37: =VLOOKUP($A37,Fundeb2025!$C:$H,3,0) -> 8045797.5 | L37: =VLOOKUP($A37,Fundeb2025!$C:$H,4,0) -> - | M37: =VLOOKUP($A37,Fundeb2025!$C:$H,5,0) -> 1305843.9 | N37: =VLOOKUP($A37,Fundeb2025!$C:$H,6,0) -> 261877.79 | O37: 7061.21 | P37: 8031.01 | Q37: 5.1304902e-05 | R37: Habilitado para o cálculo do VAAT. | S37: R$ 8.031,01
A38: 3200409 | B38: ANCHIETA | C38: 2020 | D38: 2.4853674e+08 | E38: 63013373 | F38: 70000000 | G38: 24509444 | I38: 0 | Q38: -
A39: 3200409 | B39: ANCHIETA | C39: 2021 | D39: 1.9869529e+08 | E39: 58218636 | H39: 79651872 | I39: 0 | K39: =VLOOKUP($A39,Fundeb2021!$C:$H,3,0) -> 32413907 | L39: =VLOOKUP($A39,Fundeb2021!$C:$H,4,0) -> - | M39: =VLOOKUP($A39,Fundeb2021!$C:$H,5,0) -> - | N39: =VLOOKUP($A39,Fundeb2021!$C:$H,6,0) -> - | O39: 7157.54 | P39: 7157.54 | Q39: - | R39: Habilitado para o cálculo do VAAT. | S39: R$ 4.846,26
A40: 3200409 | B40: ANCHIETA | C40: 2022 | D40: 2.9781638e+08 | E40: 80721894 | F40: 90000000 | G40: 29982942 | H40: 58664068 | I40: 0 | K40: =VLOOKUP($A40,Fundeb2022!$C:$H,3,0) -> 34926885 | L40: =VLOOKUP($A40,Fundeb2022!$C:$H,4,0) -> - | M40: =VLOOKUP($A40,Fundeb2022!$C:$H,5,0) -> - | N40: =VLOOKUP($A40,Fundeb2022!$C:$H,6,0) -> - | O40: 8129.86 | P40: 8129.86 | Q40: - | R40: Habilitado para o cálculo do VAAT. | S40: R$ 5.664,21
...

Sheet Fundeb2021
A1: Distribuição dos Repasses Referente ao Fundeb 2021
A2: ANO | B2: UF | C2: Código IBGE | D2: Entidade | E2: Receita da contribuição de estados e municípios ao Fundeb | F2: Complementação VAAF | G2: Complementação VAAT | H2: Complementação VAAR | I2: Complementação da União Total | J2: Total das receitas previstas
A3: 2021 | B3: AC | C3: 1200013 | D3: ACRELANDIA | E3: 12130854 | F3: - | G3: - | H3: - | I3: - | J3: 12130854
A4: 2021 | B4: AC | C4: 1200054 | D4: ASSIS BRASIL | E4: 7997168.3 | F4: - | G4: 439911.86 | H4: - | I4: 439911.86 | J4: 8437080.2
A5: 2021 | B5: AC | C5: 1200104 | D5: BRASILEIA | E5: 17296021 | F5: - | G5: 2025711.2 | H5: - | I5: 2025711.2 | J5: 19321732
A6: 2021 | B6: AC | C6: 1200138 | D6: BUJARI | E6: 9467886 | F6: - | G6: - | H6: - | I6: - | J6: 9467886
A7: 2021 | B7: AC | C7: 1200179 | D7: CAPIXABA | E7: 11365069 | F7: - | G7: 1089798.2 | H7: - | I7: 1089798.2 | J7: 12454867
A8: 2021 | B8: AC | C8: 1200203 | D8: CRUZEIRO DO SUL | E8: 69949116 | F8: - | G8: 15612737 | H8: - | I8: 15612737 | J8: 85561854
A9: 2021 | B9: AC | C9: 1200252 | D9: EPITACIOLANDIA | E9: 14490563 | F9: - | G9: 2736429.7 | H9: - | I9: 2736429.7 | J9: 17226993
A10: 2021 | B10: AC | C10: 1200302 | D10: FEIJO | E10: 24513130 | F10: - | G10: 2743401.8 | H10: - | I10: 2743401.8 | J10: 27256532
A11: 2021 | B11: AC | C11: 1200328 | D11: JORDAO | E11: 15149669 | F11: - | G11: 1301042.7 | H11: - | I11: 1301042.7 | J11: 16450712
A12: 2021 | B12: AC | C12: 1200336 | D12: MANCIO LIMA | E12: 18916990 | F12: - | G12: 2596538.6 | H12: - | I12: 2596538.6 | J12: 21513529
A13: 2021 | B13: AC | C13: 1200344 | D13: MANOEL URBANO | E13: 11550380 | F13: - | G13: - | H13: - | I13: - | J13: 11550380
A14: 2021 | B14: AC | C14: 1200351 | D14: MARECHAL THAUMATURGO | E14: 33215982 | F14: - | G14: 3298981.3 | H14: - | I14: 3298981.3 | J14: 36514964
A15: 2021 | B15: AC | C15: 1200385 | D15: PLACIDO DE CASTRO | E15: 12030436 | F15: - | G15: - | H15: - | I15: - | J15: 12030436
A16: 2021 | B16: AC | C16: 1200807 | D16: PORTO ACRE | E16: 12370757 | F16: - | G16: - | H16: - | I16: - | J16: 12370757
A17: 2021 | B17: AC | C17: 1200393 | D17: PORTO WALTER | E17: 18878927 | F17: - | G17: 2464579.6 | H17: - | I17: 2464579.6 | J17: 21343506
A18: 2021 | B18: AC | C18: 1200401 | D18: RIO BRANCO | E18: 1.3930273e+08 | F18: - | G18: - | H18: - | I18: - | J18: 1.3930273e+08
A19: 2021 | B19: AC | C19: 1200427 | D19: RODRIGUES ALVES | E19: 22827802 | F19: - | G19: 5418202 | H19: - | I19: 5418202 | J19: 28246004
A20: 2021 | B20: AC | C20: 1200435 | D20: SANTA ROSA DO PURUS | E20: 14916528 | F20: - | G20: 2800810.9 | H20: - | I20: 2800810.9 | J20: 17717339
A21: 2021 | B21: AC | C21: 1200500 | D21: SENA MADUREIRA | E21: 31227145 | F21: - | G21: 3511673.8 | H21: - | I21: 3511673.8 | J21: 34738819
A22: 2021 | B22: AC | C22: 1200450 | D22: SENADOR GUIOMARD | E22: 14431965 | F22: - | G22: 2320246.8 | H22: - | I22: 2320246.8 | J22: 16752212
A23: 2021 | B23: AC | C23: 1200609 | D23: TARAUACA | E23: 39648025 | F23: - | G23: 4220225.8 | H23: - | I23: 4220225.8 | J23: 43868251
A24: 2021 | B24: AC | C24: 1200708 | D24: XAPURI | E24: 7868452.3 | F24: - | G24: 1119106.4 | H24: - | I24: 1119106.4 | J24: 8987558.7
A25: 2021 | B25: AC | C25: 12 | D25: GOVERNO DO ESTADO | E25: 8.307221e+08 | F25: - | G25: - | H25: - | I25: - | J25: 8.307221e+08
A26: 2021 | B26: AL | C26: 2700102 | D26: AGUA BRANCA | E26: 21838932 | F26: 4922888 | G26: 3275629.6 | H26: - | I26: 8198517.6 | J26: 30037450
A27: 2021 | B27: AL | C27: 2700201 | D27: ANADIA | E27: 11914471 | F27: 2685736 | G27: - | H27: - | I27: 2685736 | J27: 14600207
A28: 2021 | B28: AL | C28: 2700300 | D28: ARAPIRACA | E28: 1.2846434e+08 | F28: 28958172 | G28: 10955062 | H28: - | I28: 39913235 | J28: 1.6837757e+08
A29: 2021 | B29: AL | C29: 2700409 | D29: ATALAIA | E29: 37203271 | F29: 8386286.5 | G29: - | H29: - | I29: 8386286.5 | J29: 45589558
A30: 2021 | B30: AL | C30: 2700508 | D30: BARRA DE SANTO ANTONIO | E30: 13859559 | F30: 3124193.9 | G30: 1920216.1 | H30: - | I30: 5044410 | J30: 18903969
A31: 2021 | B31: AL | C31: 2700607 | D31: BARRA DE SAO MIGUEL | E31: 8026000.3 | F31: 1809204.8 | G31: - | H31: - | I31: 1809204.8 | J31: 9835205.2
A32: 2021 | B32: AL | C32: 2700706 | D32: BATALHA | E32: 18785018 | F32: 4234481 | G32: 3934172.9 | H32: - | I32: 8168653.9 | J32: 26953672
A33: 2021 | B33: AL | C33: 2700805 | D33: BELEM | E33: 6938024.7 | F33: 1563955.5 | G33: - | H33: - | I33: 1563955.5 | J33: 8501980.2
A34: 2021 | B34: AL | C34: 2700904 | D34: BELO MONTE | E34: 7500966.8 | F34: 1690852.8 | G34: 1348171.7 | H34: - | I34: 3039024.5 | J34: 10539991
A35: 2021 | B35: AL | C35: 2701001 | D35: BOCA DA MATA | E35: 17777409 | F35: 4007347.7 | G35: 151522.78 | H35: - | I35: 4158870.5 | J35: 21936279
A36: 2021 | B36: AL | C36: 2701100 | D36: BRANQUINHA | E36: 11454451 | F36: 2582039.2 | G36: 1166517.7 | H36: - | I36: 3748556.9 | J36: 15203007
A37: 2021 | B37: AL | C37: 2701209 | D37: CACIMBINHAS | E37: 12426047 | F37: 2801054.5 | G37: 3156095.8 | H37: - | I37: 5957150.3 | J37: 18383197
A38: 2021 | B38: AL | C38: 2701308 | D38: CAJUEIRO | E38: 19756615 | F38: 4453496.3 | G38: 366124.7 | H38: - | I38: 4819621 | J38: 24576236
A39: 2021 | B39: AL | C39: 2701357 | D39: CAMPESTRE | E39: 6434030.4 | F39: 1450346.2 | G39: 585696.5 | H39: - | I39: 2036042.7 | J39: 8470073
A40: 2021 | B40: AL | C40: 2701407 | D40: CAMPO ALEGRE | E40: 43561674 | F40: 9819584.8 | G40: 11423593 | H40: - | I40: 21243178 | J40: 64804852
...

Sheet Fundeb2022
A1: Distribuição dos Repasses Referente ao Fundeb 2022
A2: ANO | B2: UF | C2: Código IBGE | D2: Entidade | E2: Receita da contribuição de estados e municípios ao Fundeb | F2: Complementação VAAF | G2: Complementação VAAT | H2: Complementação VAAR | I2: Complementação da União Total | J2: Total das receitas previstas
A3: 2022 | B3: AC | C3: 1200013 | D3: ACRELANDIA | E3: 14678796 | F3: - | G3: 2895650.8 | H3: - | I3: 2895650.8 | J3: 17574446
A4: 2022 | B4: AC | C4: 1200054 | D4: ASSIS BRASIL | E4: 9111791 | F4: - | G4: 577300.35 | H4: - | I4: 577300.35 | J4: 9689091.4
A5: 2022 | B5: AC | C5: 1200104 | D5: BRASILEIA | E5: 21306752 | F5: - | G5: 3633958.2 | H5: - | I5: 3633958.2 | J5: 24940710
A6: 2022 | B6: AC | C6: 1200138 | D6: BUJARI | E6: 11732117 | F6: - | G6: - | H6: - | I6: - | J6: 11732117
A7: 2022 | B7: AC | C7: 1200179 | D7: CAPIXABA | E7: 15094097 | F7: - | G7: 3886714.1 | H7: - | I7: 3886714.1 | J7: 18980811
A8: 2022 | B8: AC | C8: 1200203 | D8: CRUZEIRO DO SUL | E8: 83673460 | F8: - | G8: 19756449 | H8: - | I8: 19756449 | J8: 1.0342991e+08
A9: 2022 | B9: AC | C9: 1200252 | D9: EPITACIOLANDIA | E9: 16533544 | F9: - | G9: 2530151 | H9: - | I9: 2530151 | J9: 19063695
A10: 2022 | B10: AC | C10: 1200302 | D10: FEIJO | E10: 30138199 | F10: - | G10: 5833497.1 | H10: - | I10: 5833497.1 | J10: 35971696
A11: 2022 | B11: AC | C11: 1200328 | D11: JORDAO | E11: 19194357 | F11: - | G11: 4184269.5 | H11: - | I11: 4184269.5 | J11: 23378627
A12: 2022 | B12: AC | C12: 1200336 | D12: MANCIO LIMA | E12: 21973565 | F12: - | G12: 4493327.4 | H12: - | I12: 4493327.4 | J12: 26466893
A13: 2022 | B13: AC | C13: 1200344 | D13: MANOEL URBANO | E13: 15545899 | F13: - | G13: 4448814.3 | H13: - | I13: 4448814.3 | J13: 19994713
A14: 2022 | B14: AC | C14: 1200351 | D14: MARECHAL THAUMATURGO | E14: 36856945 | F14: - | G14: - | H14: - | I14: - | J14: 36856945
A15: 2022 | B15: AC | C15: 1200385 | D15: PLACIDO DE CASTRO | E15: 14321158 | F15: - | G15: 1684800.8 | H15: - | I15: 1684800.8 | J15: 16005959
A16: 2022 | B16: AC | C16: 1200807 | D16: PORTO ACRE | E16: 17852755 | F16: - | G16: 5990058.9 | H16: - | I16: 5990058.9 | J16: 23842814
A17: 2022 | B17: AC | C17: 1200393 | D17: PORTO WALTER | E17: 25363764 | F17: - | G17: 7028695 | H17: - | I17: 7028695 | J17: 32392459
A18: 2022 | B18: AC | C18: 1200401 | D18: RIO BRANCO | E18: 1.5509614e+08 | F18: - | G18: - | H18: - | I18: - | J18: 1.5509614e+08
A19: 2022 | B19: AC | C19: 1200427 | D19: RODRIGUES ALVES | E19: 28949038 | F19: - | G19: 10114189 | H19: - | I19: 10114189 | J19: 39063227
A20: 2022 | B20: AC | C20: 1200435 | D20: SANTA ROSA DO PURUS | E20: 16729846 | F20: - | G20: 1393794.9 | H20: - | I20: 1393794.9 | J20: 18123641
A21: 2022 | B21: AC | C21: 1200500 | D21: SENA MADUREIRA | E21: 36509122 | F21: - | G21: - | H21: - | I21: - | J21: 36509122
A22: 2022 | B22: AC | C22: 1200450 | D22: SENADOR GUIOMARD | E22: 15945558 | F22: - | G22: 2487745.2 | H22: - | I22: 2487745.2 | J22: 18433303
A23: 2022 | B23: AC | C23: 1200609 | D23: TARAUACA | E23: 49450644 | F23: - | G23: 10854286 | H23: - | I23: 10854286 | J23: 60304930
A24: 2022 | B24: AC | C24: 1200708 | D24: XAPURI | E24: 9069463.4 | F24: - | G24: 871566.97 | H24: - | I24: 871566.97 | J24: 9941030.3
A25: 2022 | B25: AC | C25: 12 | D25: GOVERNO DO ESTADO | E25: 1017941675 | F25: - | G25: - | H25: - | I25: - | J25: 1017941675
A26: 2022 | B26: AL | C26: 2700102 | D26: AGUA BRANCA | E26: 25380003 | F26: 4811491.5 | G26: 7232546.4 | H26: - | I26: 12044038 | J26: 37424041
A27: 2022 | B27: AL | C27: 2700201 | D27: ANADIA | E27: 14532964 | F27: 2755130.9 | G27: 3647702.4 | H27: - | I27: 6402833.4 | J27: 20935797
A28: 2022 | B28: AL | C28: 2700300 | D28: ARAPIRACA | E28: 1.4885527e+08 | F28: 28219691 | G28: 29609043 | H28: - | I28: 57828735 | J28: 2.06684e+08
A29: 2022 | B29: AL | C29: 2700409 | D29: ATALAIA | E29: 46575244 | F29: 8829644 | G29: 13384243 | H29: - | I29: 22213887 | J29: 68789130
A30: 2022 | B30: AL | C30: 2700508 | D30: BARRA DE SANTO ANTONIO | E30: 16640305 | F30: 3154636.7 | G30: 5549421.6 | H30: - | I30: 8704058.3 | J30: 25344364
A31: 2022 | B31: AL | C31: 2700607 | D31: BARRA DE SAO MIGUEL | E31: 9104742 | F31: 1726059.3 | G31: 497965.28 | H31: - | I31: 2224024.5 | J31: 11328767
A32: 2022 | B32: AL | C32: 2700706 | D32: BATALHA | E32: 21779355 | F32: 4128887.7 | G32: 5797332.5 | H32: - | I32: 9926220.2 | J32: 31705575
A33: 2022 | B33: AL | C33: 2700805 | D33: BELEM | E33: 8582608.6 | F33: 1627074.2 | G33: 2764105.4 | H33: - | I33: 4391179.6 | J33: 12973788
A34: 2022 | B34: AL | C34: 2700904 | D34: BELO MONTE | E34: 8356272.4 | F34: 1584165.9 | G34: 3034703.5 | H34: - | I34: 4618869.4 | J34: 12975142
A35: 2022 | B35: AL | C35: 2701001 | D35: BOCA DA MATA | E35: 29065713 | F35: 5510221.4 | G35: 15258400 | H35: - | I35: 20768622 | J35: 49834335
A36: 2022 | B36: AL | C36: 2701100 | D36: BRANQUINHA | E36: 14008907 | F36: 2655781.2 | G36: 4902735.4 | H36: - | I36: 7558516.6 | J36: 21567423
A37: 2022 | B37: AL | C37: 2701209 | D37: CACIMBINHAS | E37: 16106203 | F37: 3053382.6 | G37: 7005234.6 | H37: - | I37: 10058617 | J37: 26164820
... A40: 2022 | B40: AL | C40: 2701407 | D40: CAMPO ALEGRE | E40: 50970098 | F40: 9662812 | G40: 18174506 | H40: - | I40: 27837318 | J40: 78807416
A41: 2022 | B41: AL | C41: 2701506 | D41: CAMPO GRANDE | E41: 10141742 | F41: 1922651.7 | G41: - | H41: - | I41: 1922651.7 | J41: 12064394
A42: 2022 | B42: AL | C42: 2701605 | D42: CANAPI | E42: 33003835 | F42: 6256802.8 | G42: 18265009 | H42: - | I42: 24521812 | J42: 57525647
...

Sheet Fundeb2023
A1: Distribuição dos Repasses Referente ao Fundeb 2023
A2: ANO | B2: UF | C2: Código IBGE | D2: Entidade | E2: Receita da contribuição de estados e municípios ao Fundeb | F2: Complementação VAAF | G2: Complementação VAAT | H2: Complementação VAAR | I2: Complementação da União Total | J2: Total das receitas previstas
A3: 2023 | B3: AC | C3: 1200013 | D3: ACRELANDIA | E3: 14892346 | F3: - | G3: 1679713.3 | H3: - | I3: 1679713.3 | J3: 16572059
A4: 2023 | B4: AC | C4: 1200054 | D4: ASSIS BRASIL | E4: 9756657.7 | F4: - | G4: 607504.45 | H4: - | I4: 607504.45 | J4: 10364162
A5: 2023 | B5: AC | C5: 1200104 | D5: BRASILEIA | E5: 23139992 | F5: - | G5: 3880290.5 | H5: 224774.71 | I5: 4105065.2 | J5: 27245057
A6: 2023 | B6: AC | C6: 1200138 | D6: BUJARI | E6: 10808461 | F6: - | G6: - | H6: 117063.31 | I6: 117063.31 | J6: 10925524
A7: 2023 | B7: AC | C7: 1200179 | D7: CAPIXABA | E7: 15724331 | F7: - | G7: 3654805.9 | H7: 329057.92 | I7: 3983863.8 | J7: 19708195
A8: 2023 | B8: AC | C8: 1200203 | D8: CRUZEIRO DO SUL | E8: 83717407 | F8: - | G8: 10100677 | H8: 862667.3 | I8: 10963345 | J8: 94680752
A9: 2023 | B9: AC | C9: 1200252 | D9: EPITACIOLANDIA | E9: 17579365 | F9: - | G9: 912362.12 | H9: - | I9: 912362.12 | J9: 18491727
A10: 2023 | B10: AC | C10: 1200302 | D10: FEIJO | E10: 30867487 | F10: - | G10: 3673091.5 | H10: 432150.41 | I10: 4105241.9 | J10: 34972729
A11: 2023 | B11: AC | C11: 1200328 | D11: JORDAO | E11: 19644950 | F11: - | G11: 1709296.5 | H11: - | I11: 1709296.5 | J11: 21354247
A12: 2023 | B12: AC | C12: 1200336 | D12: MANCIO LIMA | E12: 23168108 | F12: - | G12: 3906158.7 | H12: 428339.56 | I12: 4334498.2 | J12: 27502606
A13: 2023 | B13: AC | C13: 1200344 | D13: MANOEL URBANO | E13: 16647694 | F13: - | G13: 4106453.6 | H13: - | I13: 4106453.6 | J13: 20754148
A14: 2023 | B14: AC | C14: 1200351 | D14: MARECHAL THAUMATURGO | E14: 38519580 | F14: - | G14: 319427.85 | H14: 346044.07 | I14: 665471.92 | J14: 39185052
A15: 2023 | B15: AC | C15: 1200385 | D15: PLACIDO DE CASTRO | E15: 15781842 | F15: - | G15: 1729525.8 | H15: - | I15: 1729525.8 | J15: 17511368
A16: 2023 | B16: AC | C16: 1200807 | D16: PORTO ACRE | E16: 17645821 | F16: - | G16: 4814989.2 | H16: - | I16: 4814989.2 | J16: 22460811
A17: 2023 | B17: AC | C17: 1200393 | D17: PORTO WALTER | E17: 24936237 | F17: - | G17: 4613835.4 | H17: 236095.91 | I17: 4849931.3 | J17: 29786168
A18: 2023 | B18: AC | C18: 1200401 | D18: RIO BRANCO | E18: 1.599511e+08 | F18: - | G18: - | H18: 3071096.3 | I18: 3071096.3 | J18: 1.630222e+08
A19: 2023 | B19: AC | C19: 1200427 | D19: RODRIGUES ALVES | E19: 30114738 | F19: - | G19: 9158405.2 | H19: - | I19: 9158405.2 | J19: 39273144
A20: 2023 | B20: AC | C20: 1200435 | D20: SANTA ROSA DO PURUS | E20: 16817031 | F20: - | G20: - | H20: 307991.24 | I20: 307991.24 | J20: 17125022
A21: 2023 | B21: AC | C21: 1200500 | D21: SENA MADUREIRA | E21: 39965330 | F21: - | G21: 4464268.8 | H21: 748300.86 | I21: 5212569.7 | J21: 45177900
A22: 2023 | B22: AC | C22: 1200450 | D22: SENADOR GUIOMARD | E22: 16021469 | F22: - | G22: - | H22: 334941.17 | I22: 334941.17 | J22: 16356410
A23: 2023 | B23: AC | C23: 1200609 | D23: TARAUACA | E23: 51849876 | F23: - | G23: 10042260 | H23: 553303.95 | I23: 10595563 | J23: 62445440
A24: 2023 | B24: AC | C24: 1200708 | D24: XAPURI | E24: 10227605 | F24: - | G24: 1430292.3 | H24: - | I24: 1430292.3 | J24: 11657897
A25: 2023 | B25: AC | C25: 12 | D25: GOVERNO DO ESTADO | E25: 1.078253e+09 | F25: - | G25: - | H25: - | I25: - | J25: 1.078253e+09
A26: 2023 | B26: AL | C26: 2700102 | D26: AGUA BRANCA | E26: 27418015 | F26: 5227962.7 | G26: 8472350.6 | H26: 343288.86 | I26: 14043602 | J26: 41461617
A27: 2023 | B27: AL | C27: 2700201 | D27: ANADIA | E27: 14623317 | F27: 2788318.5 | G27: 3743153 | H27: - | I27: 6531471.4 | J27: 21154789
A28: 2023 | B28: AL | C28: 2700300 | D28: ARAPIRACA | E28: 1.536575e+08 | F28: 29298827 | G28: 23868106 | H28: 4032334.8 | I28: 57199267 | J28: 2.1085677e+08
A29: 2023 | B29: AL | C29: 2700409 | D29: ATALAIA | E29: 49324007 | F29: 9404913.7 | G29: 22326052 | H29: - | I29: 31730966 | J29: 81054972
A30: 2023 | B30: AL | C30: 2700508 | D30: BARRA DE SANTO ANTONIO | E30: 17890788 | F30: 3411347.3 | G30: 6801085.1 | H30: 476717.02 | I30: 10689149 | J30: 28579937
A31: 2023 | B31: AL | C31: 2700607 | D31: BARRA DE SAO MIGUEL | E31: 10304058 | F31: 1964738.5 | G31: 782277.82 | H31: 316767.01 | I31: 3063783.4 | J31: 13367841
A32: 2023 | B32: AL | C32: 2700706 | D32: BATALHA | E32: 22677409 | F32: 4324041.9 | G32: 5462246.7 | H32: - | I32: 9786288.7 | J32: 32463697
A33: 2023 | B33: AL | C33: 2700805 | D33: BELEM | E33: 8985656.5 | F33: 1713350.8 | G33: 3180213 | H33: - | I33: 4893563.7 | J33: 13879220
A34: 2023 | B34: AL | C34: 2700904 | D34: BELO MONTE | E34: 10174361 | F34: 1940008.3 | G34: 5173327.9 | H34: - | I34: 7113336.3 | J34: 17287697
A35: 2023 | B35: AL | C35: 2701001 | D35: BOCA DA MATA | E35: 31199538 | F35: 5949009.1 | G35: 23056307 | H35: - | I35: 29005316 | J35: 60204854
A36: 2023 | B36: AL | C36: 2701100 | D36: BRANQUINHA | E36: 15293683 | F36: 2916141.3 | G36: 7882176.8 | H36: 206691.15 | I36: 11005009 | J36: 26298693
A37: 2023 | B37: AL | C37: 2701209 | D37: CACIMBINHAS | E37: 17842743 | F37: 3402186.4 | G37: 10027203 | H37: - | I37: 13429389 | J37: 31272133
A38: 2023 | B38: AL | C38: 2701308 | D38: CAJUEIRO | E38: 23289129 | F38: 4440682.4 | G38: 7472226.8 | H38: - | I38: 11912909 | J38: 35202038
A39: 2023 | B39: AL | C39: 2701357 | D39: CAMPESTRE | E39: 7947852.3 | F39: 1515466.2 | G39: 2374467.7 | H39: - | I39: 3889933.9 | J39: 11837786
A40: 2023 | B40: AL | C40: 2701407 | D40: CAMPO ALEGRE | E40: 55308580 | F40: 10546029 | G40: 22644439 | H40: 741290.41 | I40: 33931758 | J40: 89240338
...

Sheet Fundeb2024
A1: Distribuição dos Repasses Referente ao Fundeb 2024
A2: ANO | B2: UF | C2: Código IBGE | D2: Entidade | E2: Receita da contribuição de estados e municípios ao Fundeb | F2: Complementação VAAF | G2: Complementação VAAT | H2: Complementação VAAR | I2: Complementação da União Total | J2: Total das receitas previstas
A3: 2024 | B3: AC | C3: 1200013 | D3: ACRELANDIA | E3: 17267447 | F3: - | G3: 2106759.2 | H3: - | I3: 2106759.2 | J3: 19374207
A4: 2024 | B4: AC | C4: 1200054 | D4: ASSIS BRASIL | E4: 11263006 | F4: - | G4: 1691545.5 | H4: - | I4: 1691545.5 | J4: 12954551
A5: 2024 | B5: AC | C5: 1200104 | D5: BRASILEIA | E5: 26865464 | F5: - | G5: 3356742 | H5: 320985.39 | I5: 3677727.4 | J5: 30543191
A6: 2024 | B6: AC | C6: 1200138 | D6: BUJARI | E6: 13222303 | F6: - | G6: 1012769.2 | H6: 223271.99 | I6: 1236041.2 | J6: 14458345
A7: 2024 | B7: AC | C7: 1200179 | D7: CAPIXABA | E7: 16800901 | F7: - | G7: 347854.46 | H7: 485032.38 | I7: 832886.84 | J7: 17633788
A8: 2024 | B8: AC | C8: 1200203 | D8: CRUZEIRO DO SUL | E8: 1.0083764e+08 | F8: - | G8: 15752869 | H8: - | I8: 15752869 | J8: 1.1659051e+08
A9: 2024 | B9: AC | C9: 1200252 | D9: EPITACIOLANDIA | E9: 20820891 | F9: - | G9: 3162815.2 | H9: 647979.69 | I9: 3810794.9 | J9: 24631686
A10: 2024 | B10: AC | C10: 1200302 | D10: FEIJO | E10: 33865969 | F10: - | G10: 289298.94 | H10: 726841.64 | I10: 1016140.6 | J10: 34882110
A11: 2024 | B11: AC | C11: 1200328 | D11: JORDAO | E11: 27268875 | F11: - | G11: 8252305 | H11: - | I11: 8252305 | J11: 35521180
A12: 2024 | B12: AC | C12: 1200336 | D12: MANCIO LIMA | E12: 26618355 | F12: - | G12: 5083688.6 | H12: 688588.88 | I12: 5772277.5 | J12: 32390633
A13: 2024 | B13: AC | C13: 1200344 | D13: MANOEL URBANO | E13: 19328679 | F13: - | G13: 2874324.4 | H13: - | I13: 2874324.4 | J13: 22203003
A14: 2024 | B14: AC | C14: 1200351 | D14: MARECHAL THAUMATURGO | E14: 44044364 | F14: - | G14: 5872646.7 | H14: 440574.35 | I14: 6313221 | J14: 50357585
A15: 2024 | B15: AC | C15: 1200385 | D15: PLACIDO DE CASTRO | E15: 17877470 | F15: - | G15: 1878562.8 | H15: 479298.39 | I15: 2357861.1 | J15: 20235331
A16: 2024 | B16: AC | C16: 1200393 | D16: PORTO WALTER | E16: 28842819 | F16: - | G16: 3079327.5 | H16: 309556.7 | I16: 3388884.2 | J16: 32231703
A17: 2024 | B17: AC | C17: 1200401 | D17: RIO BRANCO | E17: 1.9444842e+08 | F17: - | G17: - | H17: 5197544.1 | I17: 5197544.1 | J17: 1.9964596e+08
A18: 2024 | B18: AC | C18: 1200427 | D18: RODRIGUES ALVES | E18: 38081686 | F18: - | G18: 11550446 | H18: 661018.62 | I18: 12211465 | J18: 50293151
A19: 2024 | B19: AC | C19: 1200435 | D19: SANTA ROSA DO PURUS | E19: 19157800 | F19: - | G19: 1096587.8 | H19: 448978.96 | I19: 1545566.8 | J19: 20703367
A20: 2024 | B20: AC | C20: 1200450 | D20: SENADOR GUIOMARD | E20: 18091280 | F20: - | G20: 834593.39 | H20: 536873.89 | I20: 1371467.3 | J20: 19462748
A21: 2024 | B21: AC | C21: 1200500 | D21: SENA MADUREIRA | E21: 46310569 | F21: - | G21: 7844221.2 | H21: 694244.32 | I21: 8538465.5 | J21: 54849035
A22: 2024 | B22: AC | C22: 1200609 | D22: TARAUACA | E22: 60402719 | F22: - | G22: 10813284 | H22: 1008278.2 | I22: 11821562 | J22: 72224281
A23: 2024 | B23: AC | C23: 1200708 | D23: XAPURI | E23: 12435363 | F23: - | G23: 2140862.3 | H23: 365050.68 | I23: 2505913 | J23: 14941276
A24: 2024 | B24: AC | C24: 1200807 | D24: PORTO ACRE | E24: 20043050 | F24: - | G24: 1037672.7 | H24: - | I24: 1037672.7 | J24: 21080723
A25: 2024 | B25: AC | C25: 12 | D25: GOVERNO DO ESTADO | E25: 1.2215914e+09 | F25: - | G25: - | H25: 13000792 | I25: 13000792 | J25: 1.2345922e+09
A26: 2024 | B26: AL | C26: 2700102 | D26: AGUA BRANCA | E26: 32806426 | F26: 6699540.1 | G26: 16109005 | H26: 473642.95 | I26: 23282188 | J26: 56088614
A27: 2024 | B27: AL | C27: 2700201 | D27: ANADIA | E27: 18239029 | F27: 3724669.8 | G27: 6477993.8 | H27: 290312.5 | I27: 10492976 | J27: 28732005
A28: 2024 | B28: AL | C28: 2700300 | D28: ARAPIRACA | E28: 1.7677765e+08 | F28: 36100518 | G28: 41270481 | H28: 6466208.2 | I28: 83837207 | J28: 2.6061486e+08
A29: 2024 | B29: AL | C29: 2700409 | D29: ATALAIA | E29: 54054112 | F29: 11038621 | G29: 15565567 | H29: 819842.18 | I29: 27424030 | J29: 81478142
A30: 2024 | B30: AL | C30: 2700508 | D30: BARRA DE SANTO ANTONIO | E30: 21003459 | F30: 4289205.8 | G30: 6815202.5 | H30: - | I30: 11104408 | J30: 32107867
A31: 2024 | B31: AL | C31: 2700607 | D31: BARRA DE SAO MIGUEL | E31: 11720771 | F31: 2393548.6 | G31: - | H31: 499524.44 | I31: 2893073 | J31: 14613844
A32: 2024 | B32: AL | C32: 2700706 | D32: BATALHA | E32: 27052028 | F32: 5524409.9 | G32: 10481179 | H32: - | I32: 16005589 | J32: 43057617
A33: 2024 | B33: AL | C33: 2700805 | D33: BELEM | E33: 11197831 | F33: 2286756.7 | G33: 4906999.4 | H33: 182741.35 | I33: 7376497.4 | J33: 18574328
A34: 2024 | B34: AL | C34: 2700904 | D34: BELO MONTE | E34: 11886754 | F34: 2427444.7 | G34: 7025257.4 | H34: 167974.37 | I34: 9620676.4 | J34: 21507430
A35: 2024 | B35: AL | C35: 2701001 | D35: BOCA DA MATA | E35: 30629465 | F35: 6254973.6 | G35: 4991185.8 | H35: 478395.09 | I35: 11724554 | J35: 42354020
A36: 2024 | B36: AL | C36: 2701100 | D36: BRANQUINHA | E36: 21802022 | F36: 4452283.8 | G36: 13915909 | H36: 336812.77 | I36: 18705005 | J36: 40507027
A37: 2024 | B37: AL | C37: 2701209 | D37: CACIMBINHAS | E37: 20073547 | F37: 4099304.6 | G37: 8655934.9 | H37: - | I37: 12755240 | J37: 32828787
A38: 2024 | B38: AL | C38: 2701308 | D38: CAJUEIRO | E38: 25910208 | F38: 5291234 | G38: 8558786.9 | H38: - | I38: 13850021 | J38: 39760229
A39: 2024 | B39: AL | C39: 2701357 | D39: CAMPESTRE | E39: 10468336 | F39: 2137783.4 | G39: 6447442.8 | H39: 164950.28 | I39: 8750176.5 | J39: 19218512
A40: 2024 | B40: AL | C40: 2701407 | D40: CAMPO ALEGRE | E40: 62347297 | F40: 12732207 | G40: 25074409 | H40: 945714.95 | I40: 38752331 | J40: 1.0109963e+08
...

Sheet Fundeb2025
A1: Distribuição dos Repasses Referente ao Fundeb 2025
A2: ANO | B2: UF | C2: Código IBGE | D2: Entidade | E2: Receita da contribuição de estados e municípios ao Fundeb | F2: Complementação VAAF | G2: Complementação VAAT | H2: Complementação VAAR | I2: Complementação da União Total | J2: Total das receitas previstas
A3: 2025 | B3: AC | C3: 1200013 | D3: ACRELANDIA | E3: 18712580 | F3: - | G3: 2697504 | H3: - | I3: 2697504 | J3: 21410084
A4: 2025 | B4: AC | C4: 1200054 | D4: ASSIS BRASIL | E4: 12845889 | F4: - | G4: 1946447 | H4: 724151.72 | I4: 2670598.8 | J4: 15516488
A5: 2025 | B5: AC | C5: 1200104 | D5: BRASILEIA | E5: 31513837 | F5: - | G5: 5610327.9 | H5: - | I5: 5610327.9 | J5: 37124165
A6: 2025 | B6: AC | C6: 1200138 | D6: BUJARI | E6: 13764050 | F6: - | G6: 1682496.8 | H6: - | I6: 1682496.8 | J6: 15446547
A7: 2025 | B7: AC | C7: 1200179 | D7: CAPIXABA | E7: 17701720 | F7: - | G7: 162157.49 | H7: - | I7: 162157.49 | J7: 17863878
A8: 2025 | B8: AC | C8: 1200203 | D8: CRUZEIRO DO SUL | E8: 1.0938158e+08 | F8: - | G8: 19401061 | H8: - | I8: 19401061 | J8: 1.2878264e+08
A9: 2025 | B9: AC | C9: 1200252 | D9: EPITACIOLANDIA | E9: 24039662 | F9: - | G9: 4075972.8 | H9: 772366.15 | I9: 4848339 | J9: 28888001
A10: 2025 | B10: AC | C10: 1200302 | D10: FEIJO | E10: 39520498 | F10: - | G10: 5039170.4 | H10: - | I10: 5039170.4 | J10: 44559668
A11: 2025 | B11: AC | C11: 1200328 | D11: JORDAO | E11: 28202029 | F11: - | G11: 7803977.4 | H11: 732685.18 | I11: 8536662.6 | J11: 36738692
A12: 2025 | B12: AC | C12: 1200336 | D12: MANCIO LIMA | E12: 29551137 | F12: - | G12: 5712863.9 | H12: - | I12: 5712863.9 | J12: 35264001
A13: 2025 | B13: AC | C13: 1200344 | D13: MANOEL URBANO | E13: 21260241 | F13: - | G13: 2894770 | H13: - | I13: 2894770 | J13: 24155011
A14: 2025 | B14: AC | C14: 1200351 | D14: MARECHAL THAUMATURGO | E14: 46230064 | F14: - | G14: 4749655 | H14: - | I14: 4749655 | J14: 50979719
A15: 2025 | B15: AC | C15: 1200385 | D15: PLACIDO DE CASTRO | E15: 19841212 | F15: - | G15: 1767957.6 | H15: - | I15: 1767957.6 | J15: 21609169
A16: 2025 | B16: AC | C16: 1200393 | D16: PORTO WALTER | E16: 28642412 | F16: - | G16: 2076111.8 | H16: - | I16: 2076111.8 | J16: 30718524
A17: 2025 | B17: AC | C17: 1200401 | D17: RIO BRANCO | E17: 2.135828e+08 | F17: - | G17: - | H17: - | I17: - | J17: 2.135828e+08
A18: 2025 | B18: AC | C18: 1200427 | D18: RODRIGUES ALVES | E18: 44144187 | F18: - | G18: 14714361 | H18: 2431418.6 | I18: 17145779 | J18: 61289966
A19: 2025 | B19: AC | C19: 1200435 | D19: SANTA ROSA DO PURUS | E19: 20021229 | F19: - | G19: 1982846.3 | H19: - | I19: 1982846.3 | J19: 22004075
A20: 2025 | B20: AC | C20: 1200450 | D20: SENADOR GUIOMARD | E20: 21271471 | F20: - | G20: 2834549.2 | H20: - | I20: 2834549.2 | J20: 24106020
A21: 2025 | B21: AC | C21: 1200500 | D21: SENA MADUREIRA | E21: 49477686 | F21: - | G21: 5280733.2 | H21: - | I21: 5280733.2 | J21: 54758419
A22: 2025 | B22: AC | C22: 1200609 | D22: TARAUACA | E22: 65498745 | F22: - | G22: 7986143.5 | H22: 1390255.7 | I22: 9376399.2 | J22: 74875144
A23: 2025 | B23: AC | C23: 1200708 | D23: XAPURI | E23: 14247915 | F23: - | G23: 2097141.7 | H23: 761037.51 | I23: 2858179.2 | J23: 17106094
A24: 2025 | B24: AC | C24: 1200807 | D24: PORTO ACRE | E24: 25870091 | F24: - | G24: 7406974.9 | H24: - | I24: 7406974.9 | J24: 33277066
A25: 2025 | B25: AC | C25: 12 | D25: GOVERNO DO ESTADO | E25: 1.3959683e+09 | F25: - | G25: - | H25: - | I25: - | J25: 1.3959683e+09
A26: 2025 | B26: AL | C26: 2700102 | D26: AGUA BRANCA | E26: 35610216 | F26: 7247832.5 | G26: 19911695 | H26: 2722686.5 | I26: 29882214 | J26: 65492430
A27: 2025 | B27: AL | C27: 2700201 | D27: ANADIA | E27: 20857671 | F27: 4245211.6 | G27: 12086248 | H27: - | I27: 16331459 | J27: 37189130
A28: 2025 | B28: AL | C28: 2700300 | D28: ARAPIRACA | E28: 1.9726249e+08 | F28: 40149307 | G28: 83735935 | H28: - | I28: 1.2388524e+08 | J28: 3.2114774e+08
A29: 2025 | B29: AL | C29: 2700409 | D29: ATALAIA | E29: 58262664 | F29: 11858339 | G29: 23650215 | H29: 4541503.8 | I29: 40050058 | J29: 98312722
A30: 2025 | B30: AL | C30: 2700508 | D30: BARRA DE SANTO ANTONIO | E30: 23156890 | F30: 4713177.1 | G30: 9057648.6 | H30: 1841063 | I30: 15611889 | J30: 38768778
A31: 2025 | B31: AL | C31: 2700607 | D31: BARRA DE SAO MIGUEL | E31: 13504993 | F31: 2748703.5 | G31: 1577281.6 | H31: 988507.04 | I31: 5314492.1 | J31: 18819485
A32: 2025 | B32: AL | C32: 2700706 | D32: BATALHA | E32: 25912060 | F32: 5273943.6 | G32: 7852320 | H32: - | I32: 13126264 | J32: 39038324
A33: 2025 | B33: AL | C33: 2700805 | D33: BELEM | E33: 11540897 | F33: 2348946.4 | G33: 5654668 | H33: - | I33: 8003614.4 | J33: 19544512
A34: 2025 | B34: AL | C34: 2700904 | D34: BELO MONTE | E34: 14166315 | F34: 2883303.9 | G34: 8888592.2 | H34: 1125849.6 | I34: 12897746 | J34: 27064060
A35: 2025 | B35: AL | C35: 2701001 | D35: BOCA DA MATA | E35: 33232540 | F35: 6763898.4 | G35: 6645184.7 | H35: 3024082.7 | I35: 16433166 | J35: 49665706
A36: 2025 | B36: AL | C36: 2701100 | D36: BRANQUINHA | E36: 22322917 | F36: 4543436.8 | G36: 14295469 | H36: 2133407.8 | I36: 20972313 | J36: 43295231
A37: 2025 | B37: AL | C37: 2701209 | D37: CACIMBINHAS | E37: 19467268 | F37: 3962219.5 | G37: 5735693.5 | H37: 804250.25 | I37: 10502163 | J37: 29969431
A38: 2025 | B38: AL | C38: 2701308 | D38: CAJUEIRO | E38: 29412628 | F38: 5986422.6 | G38: 15949919 | H38: 2016580.9 | I38: 23952923 | J38: 53365551
A39: 2025 | B39: AL | C39: 2701357 | D39: CAMPESTRE | E39: 11287999 | F39: 2297473.5 | G39: 7051211 | H39: 975235.67 | I39: 10323920 | J39: 21611919
A40: 2025 | B40: AL | C40: 2701407 | D40: CAMPO ALEGRE | E40: 75818212 | F40: 15431462 | G40: 45927438 | H40: - | I40: 61358900 | J40: 1.3717711e+08
...

Sheet HabilitaçãoVAAR2025
A1: Redes de ensino inabilitadas à complementação VAAR 2025 pelo não cumprimento de condicionalidades de melhoria de gestão previstas no art. 14, § 1º, incisos I a V, da Lei nº 14.113/2020, ou por não terem alcançado evolução em indicadores de atendimento e de melhoria da aprendizagem com redução das desigualdades previstos no art. 14, § 2º da Lei nº 14.113/2020
A2: UF | B2: Ente Federado | C2: Código IBGE | D2: Motivo
A3: AC | B3: ACRE | C3: 12 | D3: Não cumprimento do disposto no art. 14, § 1º, II, III da Lei nº 14113/2020
A4: AC | B4: ACRELANDIA | C4: 1200013 | D4: Não cumprimento do disposto no art. 14, § 1º, III da Lei nº 14113/2020
A5: AC | B5: BRASILEIA | C5: 1200104 | D5: Não cumprimento do disposto no art. 14, § 1º, III da Lei nº 14113/2020
A6: AC | B6: BUJARI | C6: 1200138 | D6: Não cumprimento do disposto no art. 14, § 1º, II da Lei nº 14113/2020
A7: AC | B7: CAPIXABA | C7: 1200179 | D7: Não cumprimento do disposto no art. 14, § 1º, II, III da Lei nº 14113/2020
A8: AC | B8: CRUZEIRO DO SUL | C8: 1200203 | D8: Não cumprimento do disposto no art. 14, § 1º, III da Lei nº 14113/2020
A9: AC | B9: FEIJO | C9: 1200302 | D9: Não cumprimento do disposto no art. 14, § 1º, III da Lei nº 14113/2020
A10: AC | B10: MANCIO LIMA | C10: 1200336 | D10: Não cumprimento do disposto no art. 14, § 1º, III da Lei nº 14113/2020
A11: AC | B11: MANOEL URBANO | C11: 1200344 | D11: Não cumprimento do disposto no art. 14, § 1º, III da Lei nº 14113/2020
A12: AC | B12: MARECHAL THAUMATURGO | C12: 1200351 | D12: Não cumprimento do disposto no art. 14, § 1º, II, III da Lei nº 14113/2020
A13: AC | B13: PLACIDO DE CASTRO | C13: 1200385 | D13: Não cumprimento do disposto no art. 14, § 1º, III da Lei nº 14113/2020
A14: AC | B14: PORTO ACRE | C14: 1200807 | D14: Não cumprimento do disposto no art. 14, § 1º, I, III da Lei nº 14113/2020
... A2760: TO | B2760: TUPIRATINS | C2760: 1721307 | D2760: Não cumprimento do disposto no art. 14, § 1º, I, III da Lei nº 14113/2020

Sheet Página1
A1: CÓDIGO MUNICÍPIO | B1: MUNICÍPIO | C1: IQE_IPM | D1: =SUM(D2:D79) -> 5490413060 | E1: ICMS_Educacional
A2: 3200102 | B2: AFONSO CLAUDIO | C2: 0.12839431 | D2: 36854003 | E2: =$D$1*0.1*C2/10 -> 7049378
A3: 3200136 | B3: AGUIA BRANCA | C3: 0.15105731 | D3: 16959475 | E3: =$D$1*0.1*C3/10 -> 8293670
A4: 3200169 | B4: AGUA DOCE DO NORTE | C4: 0.13772343 | D4: 28482349 | E4: =$D$1*0.1*C4/10 -> 7561585.1
A5: 3200201 | B5: ALEGRE | C5: 0.10388361 | D5: 22960854 | E5: =$D$1*0.1*C5/10 -> 5703639.5
A6: 3200300 | B6: ALFREDO CHAVES | C6: 0.13152102 | D6: 24271123 | E6: =$D$1*0.1*C6/10 -> 7221047.1
A7: 3200359 | B7: ALTO RIO NOVO | C7: 0.12263708 | D7: 14159146 | E7: =$D$1*0.1*C7/10 -> 6733282.2
A8: 3200409 | B8: ANCHIETA | C8: 0.12305072 | D8: 1.9112638e+08 | E8: =$D$1*0.1*C8/10 -> 6755992.6
A9: 3200508 | B9: APIACA | C9: 0.12663077 | D9: 13056255 | E9: =$D$1*0.1*C9/10 -> 6952552.6
A10: 3200607 | B10: ARACRUZ | C10: 0.12681994 | D10: 2.4581905e+08 | E10: =$D$1*0.1*C10/10 -> 6962938.7
A11: 3200706 | B11: ATILIO VIVACQUA | C11: 0.16381103 | D11: 21671614 | E11: =$D$1*0.1*C11/10 -> 8993902.4
A12: 3200805 | B12: BAIXO GUANDU | C12: 0.11590037 | D12: 29659814 | E12: =$D$1*0.1*C12/10 -> 6363409
A13: 3200904 | B13: BARRA DE SAO FRANCISCO | C13: 0.13538303 | D13: 44652576 | E13: =$D$1*0.1*C13/10 -> 7433087.6
... A79: 3205309 | B79: VITORIA | C79: 0.12963007 | D79: 5.9789514e+08 | E79: =$D$1*0.1*C79/10 -> 7117226.2

Sheet Habilitação VAAT 2023
A1: Redes de ensino inabilitadas à complementação VAAR 2023 pelo não cumprimento de condicionalidades de melhoria de gestão previstas no art. 14, § 1º, incisos I a V, da Lei nº 14.113/2020, ou por não terem alcançado evolução em indicadores de atendimento e de melhoria da aprendizagem com redução das desigualdades previstos no art. 14, § 2º da Lei nº 14.113/2020
A2: UF | B2: Ente Federado | C2: Código IBGE | D2: Motivo
A3: AC | B3: ACRE | C3: 12 | D3: Não apresentou melhoria em nenhum dos indicadores de atendimento e de melhoria da aprendizagem com redução das desigualdades, conforme metodologia constante da Portaria MEC nº 975, de 13 de dezembro de 2022
A4: AC | B4: ACRELANDIA | C4: 1200013 | D4: Não cumprimento do disposto no art. 14, § 1º, III da Lei nº 14113/2020
A5: AC | B5: ASSIS BRASIL | C5: 1200054 | D5: Não cumprimento do disposto no art. 14, § 1º, III da Lei nº 14113/2020
A6: AC | B6: EPITACIOLANDIA | C6: 1200252 | D6: Não cumprimento do disposto no art. 14, § 1º, III da Lei nº 14113/2020
A7: AC | B7: JORDAO | C7: 1200328 | D7: Não apresentou melhoria em nenhum dos indicadores de atendimento e de melhoria da aprendizagem com redução das desigualdades, conforme metodologia constante da Portaria MEC nº 975, de 13 de dezembro de 2022
A8: AC | B8: MANOEL URBANO | C8: 1200344 | D8: Não cumprimento do disposto no art. 14, § 1º, III da Lei nº 14113/2020
A9: AC | B9: PLACIDO DE CASTRO | C9: 1200385 | D9: Não cumprimento do disposto no art. 14, § 1º, III da Lei nº 14113/2020
A10: AC | B10: PORTO ACRE | C10: 1200807 | D10: Não apresentou melhoria em nenhum dos indicadores de atendimento e de melhoria da aprendizagem com redução das desigualdades, conforme metodologia constante da Portaria MEC nº 975, de 13 de dezembro de 2022
A11: AC | B11: RODRIGUES ALVES | C11: 1200427 | D11: Não cumprimento do disposto no art. 14, § 1º, III da Lei nº 14113/2020
A12: AC | B12: XAPURI | C12: 1200708 | D12: Não cumprimento do disposto no art. 14, § 1º, III da Lei nº 14113/2020
A13: AL | B13: ANADIA | C13: 2700201 | D13: Não cumprimento do disposto no art. 14, § 1º, III da Lei nº 14113/2020
A14: AL | B14: ATALAIA | C14: 2700409 | D14: Não cumprimento do disposto no art. 14, § 1º, III da Lei nº 14113/2020
... A3674: TO | B3674: WANDERLANDIA | C3674: 1722081 | D3674: Não cumprimento do disposto no art. 14, § 1º, III da Lei nº 14113/2020

Sheet Habilitação VAAT 2024
A1: Redes de ensino inabilitadas à complementação VAAR 2024 pelo não cumprimento de condicionalidades de melhoria de gestão previstas no art. 14, § 1º, incisos I a V, da Lei nº 14.113/2020, ou por não terem alcançado evolução em indicadores de atendimento e de melhoria da aprendizagem com redução das desigualdades previstos no art. 14, § 2º da Lei nº 14.113/2020
A2: UF | B2: Ente Federado | C2: Código IBGE | D2: Motivo
A3: AC | B3: ACRELANDIA | C3: 1200013 | D3: Não apresentou melhoria em nenhum dos indicadores de atendimento e de melhoria da aprendizagem com redução das desigualdades, conforme metodologia constante da Portaria MEC nº 975, de 13 de dezembro de 2022
A4: AC | B4: ASSIS BRASIL | C4: 1200054 | D4: Não cumprimento do disposto no art. 14, § 1º, III da Lei nº 14113/2020
A5: AC | B5: CRUZEIRO DO SUL | C5: 1200203 | D5: Não cumprimento do disposto no art. 14, § 1º, I da Lei nº 14113/2020
A6: AC | B6: JORDAO | C6: 1200328 | D6: Não apresentou melhoria em nenhum dos indicadores de atendimento e de melhoria da aprendizagem com redução das desigualdades, conforme metodologia constante da Portaria MEC nº 975, de 13 de dezembro de 2022
A7: AC | B7: MANOEL URBANO | C7: 1200344 | D7: Não cumprimento do disposto no art. 14, § 1º, I, III da Lei nº 14113/2020
A8: AC | B8: PORTO ACRE | C8: 1200807 | D8: Não cumprimento do disposto no art. 14, § 1º, I da Lei nº 14113/2020
A9: AL | B9: BARRA DE SANTO ANTONIO | C9: 2700508 | D9: Não cumprimento do disposto no art. 14, § 1º, I da Lei nº 14113/2020
A10: AL | B10: BATALHA | C10: 2700706 | D10: Não cumprimento do disposto no art. 14, § 1º, I, III da Lei nº 14113/2020
A11: AL | B11: CACIMBINHAS | C11: 2701209 | D11: Não cumprimento do disposto no art. 14, § 1º, III da Lei nº 14113/2020
A12: AL | B12: CAJUEIRO | C12: 2701308 | D12: Não cumprimento do disposto no art. 14, § 1º, III da Lei nº 14113/2020
A13: AL | B13: CAMPO GRANDE | C13: 2701506 | D13: Não cumprimento do disposto no art. 14, § 1º, III da Lei nº 14113/2020
A14: AL | B14: CANAPI | C14: 2701605 | D14: Não cumprimento do disposto no art. 14, § 1º, III da Lei nº 14113/2020
... A2980: TO | B2980: WANDERLANDIA | C2980: 1722081 | D2980: Não cumprimento do disposto no art. 14, § 1º, III da Lei nº 14113/2020

Sheet Habilitação VAAT 2025
A1: UF | E1: Pendência identificada
A2: ES | B2: Afonso Cláudio | C2: 3200102 | D2: Habilitado para o cálculo do VAAT.
A3: ES | B3: Água Doce do Norte | C3: 3200169 | D3: Habilitado para o cálculo do VAAT.
A4: ES | B4: Águia Branca | C4: 3200136 | D4: Habilitado para o cálculo do VAAT.
A5: ES | B5: Alegre | C5: 3200201 | D5: Habilitado para o cálculo do VAAT.
A6: ES | B6: Alfredo Chaves | C6: 3200300 | D6: Habilitado para o cálculo do VAAT.
A7: ES | B7: Alto Rio Novo | C7: 3200359 | D7: Habilitado para o cálculo do VAAT.
A8: ES | B8: Anchieta | C8: 3200409 | D8: Habilitado para o cálculo do VAAT.
A9: ES | B9: Apiacá | C9: 3200508 | D9: Habilitado para o cálculo do VAAT.
A10: ES | B10: Aracruz | C10: 3200607 | D10: Habilitado para o cálculo do VAAT.
A11: ES | B11: Atilio Vivacqua | C11: 3200706 | D11: Habilitado para o cálculo do VAAT.
A12: ES | B12: Baixo Guandu | C12: 3200805 | D12: Habilitado para o cálculo do VAAT.
A13: ES | B13: Barra de São Francisco | C13: 3200904 | D13: Habilitado para o cálculo do VAAT.
... A80: ES | B80: Vitória | C80: 3205309 | D80: Habilitado para o cálculo do VAAT.
